Workbook

Sheet List sale_DIGITAL BUILDING
A1: DIGITAL BUILDING LIST
B2: INFORMATION OF LOCATION | T2: INFORMATION OF INVENTORY
A3: No. | B3: Type | C3: Report Code | E3: Name of Block | G3: Address Detail | H3: Ward | I3: City | J3: Address (cũ) | K3: District (cũ) | L3: City (cũ) | M3: Q.ty of Floor (Tổng số tầng không bao gồm tầng gửi xe) | N3: Q.ty of Apartment | O3: Resident Traffic = (số căn hộ x 3) | P3: Visitor | Q3: Traffic/week | R3: Impression/wk | S3: Q.ty of Lift | T3: DP (Digital Poster Inside Elevator) | U3: DP/LCD (Digital Poster Outside) | V3: Total thực tế | W3: Operational Status | X3: GP (Giant Poster inside) | Y3: GP (Giant Poster outside) | Z3: Utilities Area (Shopping mall, suppermarket, 24h mart, Gym, restaurant, cinema,..) | AA3: Except (brand can't advertised) | AC3: Exploitation period (Thời gian khai thác) | AD3: Other Notes | AE3: Tên nhân sự phụ trách | AG3: Confirm thông tin
A4: BUILDING IN HO CHI MINH | AE4: BD | AF4: CS | AG4: SL màn ( Cột 15,16, 17) | AH4: TT chung cư ( Cột 8,9,10,14)
A5: =ROW()-3 -> 2 | B5: AP | C5: THEDEDGEBLOCKAIRE | E5: The D'Edge Block Aire | G5: 207 Nguyễn Văn Hưởng | H5: An Khánh | I5: Hồ Chí Minh | J5: 225 Bến Chương Dương, Phường Cô Giang | K5: 1 | L5: Hồ Chí Minh | M5: 22 | N5: 145 | O5: =N5*3 -> 435 | P5: =O5*15% -> 65.25 | Q5: =SUM(O5:P5) -> 500.25 | R5: =(O5*6*7)+(P5*2*7) -> 19183.5 | S5: 7 | T5: 6 | U5: 12 | V5: =T5+U5 -> 18 | W5: ON AIR | X5: 0 | Y5: 0 | Z5: Hồ bơi | AA5: BVS, Bạo Lực, Kinh Dị, Bất động sản | AC5: Khai thác từ ngày 01/02/2026 - 31/01/2028 | AE5: Thanh Vy | AF5: Nguyên | AG5: Confirmed | AH5: Edited
A6: =ROW()-3 -> 3 | B6: AP | C6: THEDEDGEBLOCKBREZE | E6: The D'Edge Block Breze | G6: 207 Nguyễn Văn Hưởng | H6: An Khánh | I6: Hồ Chí Minh | J6: 225 Bến Chương Dương, Phường Cô Giang | K6: 1 | L6: Hồ Chí Minh | M6: 22 | N6: 128 | O6: =N6*3 -> 384 | P6: =O6*15% -> 57.6 | Q6: =SUM(O6:P6) -> 441.6 | R6: =(O6*6*7)+(P6*2*7) -> 16934.4 | S6: 7 | T6: 6 | U6: 12 | V6: =T6+U6 -> 18 | W6: ON AIR | X6: 0 | Y6: 0 | Z6: Gym | AA6: BVS, Bạo Lực, Kinh Dị, Bất động sản | AC6: Khai thác từ ngày 01/02/2026 - 31/01/2028 | AE6: Thanh Vy | AF6: Nguyên | AG6: Confirmed | AH6: Edited
A7: =ROW()-3 -> 4 | B7: AP | C7: EMPIRECITYCOVERESIDENCESTHAP1 | E7: Empire City Cove Residences - Tháp 1 | G7: 186/6A Thủ Thiêm | H7: An Khánh | I7: Hồ Chí Minh | M7: 15 | N7: 45 | O7: =N7*3 -> 135 | P7: =O7*15% -> 20.25 | Q7: =SUM(O7:P7) -> 155.25 | R7: =(O7*7*6)+(P7*7*2) -> 5953.5 | S7: 4 | T7: 4 | U7: 6 | V7: =T7+U7 -> 10 | W7: ON AIR | X7: 0 | Y7: 0 | Z7: Gym, Hồ bơi, Coffeeshop | AA7: BĐS, Bạo lực, Kinh dị, BVS | AC7: Khai thác từ ngày 1/6/2026 - 31/5/2027 | AE7: Nhiên | AF7: Nguyên | AG7: Confirmed | AH7: Edited
A8: =ROW()-3 -> 5 | B8: AP | C8: EMPIRECITYCOVERESIDENCESTHAP2 | E8: Empire City Cove Residences - Tháp 2 | G8: 186/6A Thủ Thiêm | H8: An Khánh | I8: Hồ Chí Minh | M8: 15 | N8: 91 | O8: =N8*3 -> 273 | P8: =O8*15% -> 40.95 | Q8: =SUM(O8:P8) -> 313.95 | R8: =(O8*7*6)+(P8*7*2) -> 12039.3 | S8: 5 | T8: 6 | U8: 9 | V8: =T8+U8 -> 15 | W8: ON AIR | X8: 0 | Y8: 0 | Z8: Gym, Hồ bơi, Coffeeshop | AA8: BĐS, Bạo lực, Kinh dị, BVS | AC8: Khai thác từ ngày 1/6/2026 - 31/5/2027 | AE8: Nhiên | AF8: Nguyên | AG8: Confirmed | AH8: Edited
A9: =ROW()-3 -> 6 | B9: AP | C9: THEPRIVIABLOCKA | E9: The Privia Block A | G9: 158 An Dương Vương | H9: An Lạc | I9: Hồ Chí Minh | M9: 20 | N9: 348 | O9: =N9*3 -> 1044 | P9: =O9*15% -> 156.6 | Q9: =SUM(O9:P9) -> 1200.6 | R9: =(O9*6*7)+(P9*2*7) -> 46040.4 | S9: 4 | T9: 8 | U9: 6 | V9: =T9+U9 -> 14 | W9: ON AIR | X9: 0 | Y9: 12 | Z9: Coffe Trung Nguyên, Shophouse | AA9: BVS, Bạo Lực, Kinh Dị, Bất động sản | AC9: Khai thác từ ngày 15/01/2026 - 14/01/2029 | AE9: Hà | AF9: Nguyên | AG9: Confirmed | AH9: Confirmed
A10: =ROW()-3 -> 7 | B10: AP | C10: THEPRIVIABLOCKB | E10: The Privia Block B | G10: 158 An Dương Vương | H10: An Lạc | I10: Hồ Chí Minh | M10: 20 | N10: 348 | O10: =N10*3 -> 1044 | P10: =O10*15% -> 156.6 | Q10: =SUM(O10:P10) -> 1200.6 | R10: =(O10*6*7)+(P10*2*7) -> 46040.4 | S10: 4 | T10: 8 | U10: 8 | V10: =T10+U10 -> 16 | W10: ON AIR | X10: 0 | Y10: 16 | Z10: Hồ bơi, Gym, Yoga, Đọc sách, BBQ, King Mart | AA10: BVS, Bạo Lực, Kinh Dị, Bất động sản | AC10: Khai thác từ ngày 15/01/2026 - 14/01/2029 | AE10: Hà | AF10: Nguyên | AG10: Confirmed | AH10: Confirmed
A11: =ROW()-3 -> 8 | B11: AP | C11: THEPRIVIABLOCKC | E11: The Privia Block C | G11: 158 An Dương Vương | H11: An Lạc | I11: Hồ Chí Minh | J11: 225 Bến Chương Dương, Phường Cô Giang | K11: 1 | L11: Hồ Chí Minh | M11: 20 | N11: 348 | O11: =N11*3 -> 1044 | P11: =O11*15% -> 156.6 | Q11: =SUM(O11:P11) -> 1200.6 | R11: =(O11*6*7)+(P11*2*7) -> 46040.4 | S11: 4 | T11: 8 | U11: 6 | V11: =T11+U11 -> 14 | W11: ON AIR | X11: 0 | Y11: 12 | Z11: Trường mầm non, sân chơi trẻ em | AA11: BVS, Bạo Lực, Kinh Dị, Bất động sản | AC11: Khai thác từ ngày 15/01/2026 - 14/01/2029 | AE11: Hà | AF11: Nguyên | AG11: Confirmed | AH11: Confirmed
A12: =ROW()-3 -> 9 | B12: OB | C12: THESUNAVENUESO1 | E12: The Sun Avenue S01 | G12: 28 Mai Chí Thọ | H12: Bình Trưng | I12: Hồ Chí Minh | J12: 43-45 Ngõ 130 Đốc Ngữ, Phường Vĩnh Phú | K12: Ba Đình | L12: Hà Nội | M12: 28 | N12: 66 | O12: =N12*3 -> 198 | P12: =O12*15% -> 29.7 | Q12: =SUM(O12:P12) -> 227.7 | R12: =(O12*7*6)+(P12*7*2) -> 8731.8 | S12: 3 | T12: 4 | U12: 4 | V12: =T12+U12 -> 8 | W12: ON AIR | X12: 0 | Y12: =SUMIF($W$126,"ON GOING",V126) -> 0 | Z12: Siêu thị, cafe, quán ăn, Salon, nhà thuốc, Gym, Hồ bơi, … | AA12: BVS, Bạo Lực, Kinh Dị,.. | AC12: Khai thác từ ngày 1/2/2026 - 31/1/2027 | AE12: Tân | AF12: Nguyên | AG12: Confirmed | AH12: Reviewing
A13: =ROW()-3 -> 10 | B13: OB | C13: THESUNAVENUESO2 | E13: The Sun Avenue S02 | G13: 28 Mai Chí Thọ | H13: Bình Trưng | I13: Hồ Chí Minh | J13: 43-45 Ngõ 130 Đốc Ngữ, Phường Vĩnh Phú | K13: Ba Đình | L13: Hà Nội | M13: 30 | N13: 90 | O13: =N13*3 -> 270 | P13: =O13*15% -> 40.5 | Q13: =SUM(O13:P13) -> 310.5 | R13: =(O13*7*6)+(P13*7*2) -> 11907 | S13: 3 | T13: 4 | U13: 4 | V13: =T13+U13 -> 8 | W13: ON AIR | X13: 0 | Y13: =SUMIF($W$126,"ON GOING",V127) -> 0 | Z13: Siêu thị, cafe, quán ăn, Salon, nhà thuốc, Gym, Hồ bơi, … | AA13: BVS, Bạo Lực, Kinh Dị,.. | AC13: Khai thác từ ngày 1/2/2026 - 31/1/2027 | AE13: Tân | AF13: Nguyên | AG13: Confirmed | AH13: Reviewing
A14: =ROW()-3 -> 11 | B14: OB | C14: THESUNAVENUESO3 | E14: The Sun Avenue S03 | G14: 28 Mai Chí Thọ | H14: Bình Trưng | I14: Hồ Chí Minh | J14: 43-45 Ngõ 130 Đốc Ngữ, Phường Vĩnh Phú | K14: Ba Đình | L14: Hà Nội | M14: 30 | N14: 102 | O14: =N14*3 -> 306 | P14: =O14*15% -> 45.9 | Q14: =SUM(O14:P14) -> 351.9 | R14: =(O14*7*6)+(P14*7*2) -> 13494.6 | S14: 3 | T14: 4 | U14: 4 | V14: =T14+U14 -> 8 | W14: ON AIR | X14: 0 | Y14: =SUMIF($W$126,"ON GOING",V128) -> 0 | Z14: Siêu thị, cafe, quán ăn, Salon, nhà thuốc, Gym, Hồ bơi, … | AA14: BVS, Bạo Lực, Kinh Dị,.. | AC14: Khai thác từ ngày 1/2/2026 - 31/1/2027 | AE14: Tân | AF14: Nguyên | AG14: Confirmed | AH14: Reviewing
A15: =ROW()-3 -> 12 | B15: OB | C15: THESUNAVENUESO4 | E15: The Sun Avenue S04 | G15: 28 Mai Chí Thọ | H15: Bình Trưng | I15: Hồ Chí Minh | J15: 43-45 Ngõ 130 Đốc Ngữ, Phường Vĩnh Phú | K15: Ba Đình | L15: Hà Nội | M15: 29 | N15: 92 | O15: =N15*3 -> 276 | P15: =O15*15% -> 41.4 | Q15: =SUM(O15:P15) -> 317.4 | R15: =(O15*7*6)+(P15*7*2) -> 12171.6 | S15: 3 | T15: 4 | U15: 4 | V15: =T15+U15 -> 8 | W15: ON AIR | X15: 0 | Y15: =SUMIF($W$126,"ON GOING",V129) -> 0 | Z15: Siêu thị, cafe, quán ăn, Salon, nhà thuốc, Gym, Hồ bơi, … | AA15: BVS, Bạo Lực, Kinh Dị,.. | AC15: Khai thác từ ngày 1/2/2026 - 31/1/2027 | AE15: Tân | AF15: Nguyên | AG15: Confirmed | AH15: Reviewing
A16: =ROW()-3 -> 13 | B16: OB | C16: THESUNAVENUESO5 | E16: The Sun Avenue S05 | G16: 28 Mai Chí Thọ | H16: Bình Trưng | I16: Hồ Chí Minh | J16: 43-45 Ngõ 130 Đốc Ngữ, Phường Vĩnh Phú | K16: Ba Đình | L16: Hà Nội | M16: 29 | N16: 84 | O16: =N16*3 -> 252 | P16: =O16*15% -> 37.8 | Q16: =SUM(O16:P16) -> 289.8 | R16: =(O16*7*6)+(P16*7*2) -> 11113.2 | S16: 3 | T16: 4 | U16: 4 | V16: =T16+U16 -> 8 | W16: ON AIR | X16: 0 | Y16: =SUMIF($W$126,"ON GOING",V130) -> 0 | Z16: Siêu thị, cafe, quán ăn, Salon, nhà thuốc, Gym, Hồ bơi, … | AA16: BVS, Bạo Lực, Kinh Dị,.. | AC16: Khai thác từ ngày 1/2/2026 - 31/1/2027 | AE16: Tân | AF16: Nguyên | AG16: Confirmed | AH16: Reviewing
A17: =ROW()-3 -> 14 | B17: OB | C17: THESUNAVENUESO6 | E17: The Sun Avenue S06 | G17: 28 Mai Chí Thọ | H17: Bình Trưng | I17: Hồ Chí Minh | J17: 43-45 Ngõ 130 Đốc Ngữ, Phường Vĩnh Phú | K17: Ba Đình | L17: Hà Nội | M17: 29 | N17: 66 | O17: =N17*3 -> 198 | P17: =O17*15% -> 29.7 | Q17: =SUM(O17:P17) -> 227.7 | R17: =(O17*7*6)+(P17*7*2) -> 8731.8 | S17: 2 | T17: 2 | U17: 2 | V17: =T17+U17 -> 4 | W17: ON AIR | X17: 0 | Y17: =SUMIF($W$126,"ON GOING",V131) -> 0 | Z17: Siêu thị, cafe, quán ăn, Salon, nhà thuốc, Gym, Hồ bơi, … | AA17: BVS, Bạo Lực, Kinh Dị,.. | AC17: Khai thác từ ngày 1/2/2026 - 31/1/2027 | AE17: Tân | AF17: Nguyên | AG17: Confirmed | AH17: Reviewing
A18: =ROW()-3 -> 15 | B18: OB | C18: THESUNAVENUESO7 | E18: The Sun Avenue S07 | G18: 28 Mai Chí Thọ | H18: Bình Trưng | I18: Hồ Chí Minh | M18: 28 | N18: 56 | O18: =N18*3 -> 168 | P18: =O18*15% -> 25.2 | Q18: =SUM(O18:P18) -> 193.2 | R18: =(O18*7*6)+(P18*7*2) -> 7408.8 | S18: 2 | T18: 2 | U18: 2 | V18: =T18+U18 -> 4 | W18: ON AIR | X18: 0 | Y18: =SUMIF($W$126,"ON GOING",V132) -> 0 | Z18: Siêu thị, cafe, quán ăn, Salon, nhà thuốc, Gym, Hồ bơi, … | AA18: BVS, Bạo Lực, Kinh Dị,.. | AC18: Khai thác từ ngày 1/2/2026 - 31/1/2027 | AE18: Tân | AF18: Nguyên | AG18: Confirmed | AH18: Reviewing
A19: =ROW()-3 -> 16 | B19: OB | C19: THESUNAVENUESO8 | E19: The Sun Avenue S08 | G19: 28 Mai Chí Thọ | H19: Bình Trưng | I19: Hồ Chí Minh | J19: 15-17 Ngọc Khánh | K19: Ba Đình | L19: Hà Nội | M19: 26 | N19: 124 | O19: =N19*3 -> 372 | P19: =O19*15% -> 55.8 | Q19: =SUM(O19:P19) -> 427.8 | R19: =(O19*7*6)+(P19*7*2) -> 16405.2 | S19: 2 | T19: 2 | U19: 2 | V19: =T19+U19 -> 4 | W19: ON AIR | X19: 0 | Y19: =SUMIF($W$126,"ON GOING",V133) -> 0 | Z19: Siêu thị, cafe, quán ăn, Salon, nhà thuốc, Gym, Hồ bơi, … | AA19: BVS, Bạo Lực, Kinh Dị,.. | AC19: Khai thác từ ngày 1/2/2026 - 31/1/2027 | AE19: Tân | AF19: Nguyên | AG19: Confirmed | AH19: Reviewing
A20: =ROW()-3 -> 17 | B20: AP | C20: THESUNAVENUESA1 | E20: The Sun Avenue SA1 | G20: 28 Mai Chí Thọ | H20: Bình Trưng | I20: Hồ Chí Minh | J20: 43-45 Ngõ 130 Đốc Ngữ, Phường Vĩnh Phú | K20: Ba Đình | L20: Hà Nội | M20: 28 | N20: 300 | O20: =N20*3 -> 900 | P20: =O20*15% -> 135 | Q20: =SUM(O20:P20) -> 1035 | R20: =(O20*7*6)+(P20*7*2) -> 39690 | S20: 5 | T20: 8 | U20: 6 | V20: =T20+U20 -> 14 | W20: ON AIR | X20: 0 | Y20: =SUMIF($W$126,"ON GOING",V134) -> 0 | Z20: Siêu thị, cafe, quán ăn, Salon, nhà thuốc, Gym, Hồ bơi, … | AA20: BVS, Bạo Lực, Kinh Dị,.. | AC20: Khai thác từ ngày 1/2/2026 - 31/1/2027 | AE20: Tân | AF20: Nguyên | AG20: Confirmed | AH20: Reviewing
A21: =ROW()-3 -> 18 | B21: AP | C21: THESUNAVENUESA2 | E21: The Sun Avenue SA2 | G21: 28 Mai Chí Thọ | H21: Bình Trưng | I21: Hồ Chí Minh | J21: 43-45 Ngõ 130 Đốc Ngữ, Phường Vĩnh Phú | K21: Ba Đình | L21: Hà Nội | M21: 30 | N21: 324 | O21: =N21*3 -> 972 | P21: =O21*15% -> 145.8 | Q21: =SUM(O21:P21) -> 1117.8 | R21: =(O21*7*6)+(P21*7*2) -> 42865.2 | S21: 5 | T21: 8 | U21: 6 | V21: =T21+U21 -> 14 | W21: ON AIR | X21: 0 | Y21: =SUMIF($W$126,"ON GOING",V135) -> 0 | Z21: Siêu thị, cafe, quán ăn, Salon, nhà thuốc, Gym, Hồ bơi, … | AA21: BVS, Bạo Lực, Kinh Dị,.. | AC21: Khai thác từ ngày 1/2/2026 - 31/1/2027 | AE21: Tân | AF21: Nguyên | AG21: Confirmed | AH21: Reviewing
A22: =ROW()-3 -> 19 | B22: AP | C22: THESUNAVENUESA3 | E22: The Sun Avenue SA3 | G22: 28 Mai Chí Thọ | H22: Bình Trưng | I22: Hồ Chí Minh | J22: 43-45 Ngõ 130 Đốc Ngữ, Phường Vĩnh Phú | K22: Ba Đình | L22: Hà Nội | M22: 30 | N22: 324 | O22: =N22*3 -> 972 | P22: =O22*15% -> 145.8 | Q22: =SUM(O22:P22) -> 1117.8 | R22: =(O22*7*6)+(P22*7*2) -> 42865.2 | S22: 5 | T22: 8 | U22: 6 | V22: =T22+U22 -> 14 | W22: ON AIR | X22: 0 | Y22: =SUMIF($W$126,"ON GOING",V136) -> 0 | Z22: Siêu thị, cafe, quán ăn, Salon, nhà thuốc, Gym, Hồ bơi, … | AA22: BVS, Bạo Lực, Kinh Dị,.. | AC22: Khai thác từ ngày 1/2/2026 - 31/1/2027 | AE22: Tân | AF22: Nguyên | AG22: Confirmed | AH22: Reviewing
A23: =ROW()-3 -> 20 | B23: AP | C23: THESUNAVENUESA4 | E23: The Sun Avenue SA4 | G23: 28 Mai Chí Thọ | H23: Bình Trưng | I23: Hồ Chí Minh | J23: 43-45 Ngõ 130 Đốc Ngữ, Phường Vĩnh Phú | K23: Ba Đình | L23: Hà Nội | M23: 29 | N23: 324 | O23: =N23*3 -> 972 | P23: =O23*15% -> 145.8 | Q23: =SUM(O23:P23) -> 1117.8 | R23: =(O23*7*6)+(P23*7*2) -> 42865.2 | S23: 5 | T23: 8 | U23: 6 | V23: =T23+U23 -> 14 | W23: ON AIR | X23: 0 | Y23: =SUMIF($W$126,"ON GOING",V137) -> 0 | Z23: Siêu thị, cafe, quán ăn, Salon, nhà thuốc, Gym, Hồ bơi, … | AA23: BVS, Bạo Lực, Kinh Dị,.. | AC23: Khai thác từ ngày 1/2/2026 - 31/1/2027 | AE23: Tân | AF23: Nguyên | AG23: Confirmed | AH23: Reviewing
A24: =ROW()-3 -> 21 | B24: AP | C24: THESUNAVENUESA5 | E24: The Sun Avenue SA5 | G24: 28 Mai Chí Thọ | H24: Bình Trưng | I24: Hồ Chí Minh | J24: 43-45 Ngõ 130 Đốc Ngữ, Phường Vĩnh Phú | K24: Ba Đình | L24: Hà Nội | M24: 29 | N24: 312 | O24: =N24*3 -> 936 | P24: =O24*15% -> 140.4 | Q24: =SUM(O24:P24) -> 1076.4 | R24: =(O24*7*6)+(P24*7*2) -> 41277.6 | S24: 5 | T24: 8 | U24: 6 | V24: =T24+U24 -> 14 | W24: ON AIR | X24: 0 | Y24: =SUMIF($W$126,"ON GOING",V138) -> 0 | Z24: Siêu thị, cafe, quán ăn, Salon, nhà thuốc, Gym, Hồ bơi, … | AA24: BVS, Bạo Lực, Kinh Dị,.. | AC24: Khai thác từ ngày 1/2/2026 - 31/1/2027 | AE24: Tân | AF24: Nguyên | AG24: Confirmed | AH24: Reviewing
A25: =ROW()-3 -> 22 | B25: AP | C25: THESUNAVENUESA6 | E25: The Sun Avenue SA6 | G25: 28 Mai Chí Thọ | H25: Bình Trưng | I25: Hồ Chí Minh | J25: 28 | K25: 250 | L25: 750 | M25: 29 | N25: 208 | O25: =N25*3 -> 624 | P25: =O25*15% -> 93.6 | Q25: =SUM(O25:P25) -> 717.6 | R25: =(O25*7*6)+(P25*7*2) -> 27518.4 | S25: 4 | T25: 6 | U25: 6 | V25: =T25+U25 -> 12 | W25: ON AIR | X25: 0 | Y25: =SUMIF($W$126,"ON GOING",V139) -> 0 | Z25: Siêu thị, cafe, quán ăn, Salon, nhà thuốc, Gym, Hồ bơi, … | AA25: BVS, Bạo Lực, Kinh Dị,.. | AC25: Khai thác từ ngày 1/2/2026 - 31/1/2027 | AE25: Tân | AF25: Nguyên | AG25: Confirmed | AH25: Reviewing
A26: =ROW()-3 -> 23 | B26: AP | C26: THESUNAVENUESA7 | E26: The Sun Avenue SA7 | G26: 28 Mai Chí Thọ | H26: Bình Trưng | I26: Hồ Chí Minh | J26: 28 | K26: 250 | L26: 750 | M26: 28 | N26: 200 | O26: =N26*3 -> 600 | P26: =O26*15% -> 90 | Q26: =SUM(O26:P26) -> 690 | R26: =(O26*7*6)+(P26*7*2) -> 26460 | S26: 4 | T26: 6 | U26: 4 | V26: =T26+U26 -> 10 | W26: ON AIR | X26: 0 | Y26: =SUMIF($W$126,"ON GOING",V140) -> 0 | Z26: Siêu thị, cafe, quán ăn, Salon, nhà thuốc, Gym, Hồ bơi, … | AA26: BVS, Bạo Lực, Kinh Dị,.. | AC26: Khai thác từ ngày 1/2/2026 - 31/1/2027 | AE26: Tân | AF26: Nguyên | AG26: Confirmed | AH26: Reviewing
A27: =ROW()-3 -> 24 | B27: AP | C27: THESUNAVENUESA8 | E27: The Sun Avenue SA8 | G27: 28 Mai Chí Thọ | H27: Bình Trưng | I27: Hồ Chí Minh | M27: 26 | N27: 228 | O27: =N27*3 -> 684 | P27: =O27*15% -> 102.6 | Q27: =SUM(O27:P27) -> 786.6 | R27: =(O27*7*6)+(P27*7*2) -> 30164.4 | S27: 4 | T27: 6 | U27: 4 | V27: =T27+U27 -> 10 | W27: ON AIR | X27: 0 | Y27: =SUMIF($W$126,"ON GOING",V141) -> 0 | Z27: Siêu thị, cafe, quán ăn, Salon, nhà thuốc, Gym, Hồ bơi, … | AA27: BVS, Bạo Lực, Kinh Dị,.. | AC27: Khai thác từ ngày 1/2/2026 - 31/1/2027 | AE27: Tân | AF27: Nguyên | AG27: Confirmed | AH27: Reviewing
A28: =ROW()-3 -> 25 | B28: AP | C28: THUTHIEMGARDENBLOCKA | E28: Thủ Thiêm Garden Block A | G28: 269 Liên Phường | H28: Phước Long | I28: Hồ Chí Minh | M28: 15 | N28: 185 | O28: =N28*3 -> 555 | P28: =O28*15% -> 83.25 | Q28: =SUM(O28:P28) -> 638.25 | R28: =(O28*7*6)+(P28*7*2) -> 24475.5 | S28: 3 | T28: 4 | U28: 6 | V28: =T28+U28 -> 10 | W28: ON AIR | X28: 3 | Y28: 9 | Z28: Winmart | AA28: BVS, Bạo Lực, Kinh Dị,.. | AC28: Khai thác từ ngày 25/05/20206 - 24/06/2029 | AE28: Hà | AF28: Nguyên | AG28: Edited | AH28: Confirmed
A29: =ROW()-3 -> 26 | B29: AP | C29: THUTHIEMGARDENBLOCKB | E29: Thủ Thiêm Garden Block B | G29: 269 Liên Phường | H29: Phước Long | I29: Hồ Chí Minh | M29: 15 | N29: 190 | O29: =N29*3 -> 570 | P29: =O29*15% -> 85.5 | Q29: =SUM(O29:P29) -> 655.5 | R29: =(O29*7*6)+(P29*7*2) -> 25137 | S29: 3 | T29: 4 | U29: 6 | V29: =T29+U29 -> 10 | W29: ON AIR | X29: 3 | Y29: 9 | Z29: Hồ bơi | AA29: BVS, Bạo Lực, Kinh Dị,.. | AC29: Khai thác từ ngày 25/05/20206 - 24/06/2029 | AE29: Hà | AF29: Nguyên | AG29: Confirmed | AH29: Confirmed
A30: =ROW()-3 -> 27 | B30: AP | C30: AKARICITYBLOCKAK1 | E30: Akari City Block AK1 | G30: 77 Võ Văn Kiệt | H30: An Lạc | I30: Hồ Chí Minh | M30: 24 | N30: 310 | O30: =N30*3 -> 930 | P30: =O30*15% -> 139.5 | Q30: =SUM(O30:P30) -> 1069.5 | R30: =(O30*7*6)+(P30*7*2) -> 41013 | S30: 4 | T30: 6 | U30: 6 | V30: =T30+U30 -> 12 | W30: ON GOING | X30: 0 | Y30: =SUMIF($W$126,"ON GOING",V126) -> 0 | Z30: Hồ bơi, highlands, khu vui chơi, Convenience store, Gym | AA30: BVS, Bạo Lực, Kinh Dị,.. | AC30: Khai thác từ ngày 1/7/2026 đến ngày 30/6/2027 | AE30: Nhiên | AG30: Confirmed | AH30: Reviewing
A31: =ROW()-3 -> 28 | B31: AP | C31: AKARICITYBLOCKAK2 | E31: Akari City Block AK2 | G31: 77 Võ Văn Kiệt | H31: An Lạc | I31: Hồ Chí Minh | M31: 24 | N31: 310 | O31: =N31*3 -> 930 | P31: =O31*15% -> 139.5 | Q31: =SUM(O31:P31) -> 1069.5 | R31: =(O31*7*6)+(P31*7*2) -> 41013 | S31: 4 | T31: 6 | U31: 6 | V31: =T31+U31 -> 12 | W31: ON GOING | X31: 0 | Y31: =SUMIF($W$126,"ON GOING",V127) -> 0 | Z31: Hồ bơi, highlands, khu vui chơi, Convenience store, Gym | AA31: BVS, Bạo Lực, Kinh Dị,.. | AC31: Khai thác từ ngày 1/7/2026 đến ngày 30/6/2027 | AE31: Nhiên | AG31: Confirmed | AH31: Reviewing
A32: =ROW()-3 -> 29 | B32: AP | C32: AKARICITYBLOCKAK3 | E32: Akari City Block AK3 | G32: 77 Võ Văn Kiệt | H32: An Lạc | I32: Hồ Chí Minh | M32: 24 | N32: 310 | O32: =N32*3 -> 930 | P32: =O32*15% -> 139.5 | Q32: =SUM(O32:P32) -> 1069.5 | R32: =(O32*7*6)+(P32*7*2) -> 41013 | S32: 4 | T32: 6 | U32: 6 | V32: =T32+U32 -> 12 | W32: ON GOING | X32: 0 | Y32: =SUMIF($W$126,"ON GOING",V128) -> 0 | Z32: Hồ bơi, highlands, khu vui chơi, Convenience store, Gym | AA32: BVS, Bạo Lực, Kinh Dị,.. | AC32: Khai thác từ ngày 1/7/2026 đến ngày 30/6/2027 | AE32: Nhiên | AG32: Confirmed | AH32: Reviewing
A33: =ROW()-3 -> 30 | B33: AP | C33: AKARICITYBLOCKAK4 | E33: Akari City Block AK4 | G33: 77 Võ Văn Kiệt | H33: An Lạc | I33: Hồ Chí Minh | M33: 24 | N33: 310 | O33: =N33*3 -> 930 | P33: =O33*15% -> 139.5 | Q33: =SUM(O33:P33) -> 1069.5 | R33: =(O33*7*6)+(P33*7*2) -> 41013 | S33: 4 | T33: 6 | U33: 6 | V33: =T33+U33 -> 12 | W33: ON GOING | X33: 0 | Y33: =SUMIF($W$126,"ON GOING",V129) -> 0 | Z33: Hồ bơi, highlands, khu vui chơi, Convenience store, Gym | AA33: BVS, Bạo Lực, Kinh Dị,.. | AC33: Khai thác từ ngày 1/7/2026 đến ngày 30/6/2027 | AE33: Nhiên | AG33: Confirmed | AH33: Reviewing
A34: =ROW()-3 -> 31 | B34: AP | C34: AKARICITYBLOCKAK5 | E34: Akari City Block AK5 | G34: 77 Võ Văn Kiệt | H34: An Lạc | I34: Hồ Chí Minh | M34: 24 | N34: 310 | O34: =N34*3 -> 930 | P34: =O34*15% -> 139.5 | Q34: =SUM(O34:P34) -> 1069.5 | R34: =(O34*7*6)+(P34*7*2) -> 41013 | S34: 4 | T34: 6 | U34: 6 | V34: =T34+U34 -> 12 | W34: ON GOING | X34: 0 | Y34: =SUMIF($W$126,"ON GOING",V130) -> 0 | Z34: Hồ bơi, highlands, khu vui chơi, Convenience store, Gym | AA34: BVS, Bạo Lực, Kinh Dị,.. | AC34: Khai thác từ ngày 1/7/2026 đến ngày 30/6/2027 | AE34: Nhiên | AG34: Confirmed | AH34: Reviewing
A35: =ROW()-3 -> 32 | B35: AP | C35: AKARICITYBLOCKAK6 | E35: Akari City Block AK6 | G35: 77 Võ Văn Kiệt | H35: An Lạc | I35: Hồ Chí Minh | M35: 24 | N35: 310 | O35: =N35*3 -> 930 | P35: =O35*15% -> 139.5 | Q35: =SUM(O35:P35) -> 1069.5 | R35: =(O35*7*6)+(P35*7*2) -> 41013 | S35: 4 | T35: 6 | U35: 6 | V35: =T35+U35 -> 12 | W35: ON GOING | X35: 0 | Y35: =SUMIF($W$126,"ON GOING",V131) -> 0 | Z35: Hồ bơi, highlands, khu vui chơi, Convenience store, Gym | AA35: BVS, Bạo Lực, Kinh Dị,.. | AC35: Khai thác từ ngày 1/7/2026 đến ngày 30/6/2027 | AE35: Nhiên | AG35: Confirmed | AH35: Reviewing
A36: =ROW()-3 -> 33 | B36: AP | C36: =UPPER(SUBSTITUTE(E36, " ", "")) -> BCONSCITYBLOCKA1A | E36: Bcons City Block A1a | G36: 57-60 Thống Nhất | H36: Đông Hòa | I36: Hồ Chí Minh | M36: 22 | N36: 650 | O36: =N36*3 -> 1950 | P36: =O36*15% -> 292.5 | Q36: =SUM(O36:P36) -> 2242.5 | R36: =(O36*7*6)+(P36*7*2) -> 85995 | S36: 3 | T36: 6 | U36: 8 | V36: =T36+U36 -> 14 | W36: ON GOING | X36: 0 | Y36: =SUMIF($W$126,"ON GOING",V132) -> 0 | Z36: Shophouse, khu vui chơi | AA36: BVS, Bạo Lực, Kinh Dị, Bất động sản,..
A37: =ROW()-3 -> 34 | B37: AP | C37: =UPPER(SUBSTITUTE(E37, " ", "")) -> BCONSCITYBLOCKA1B | E37: Bcons City Block A1b | G37: 57-60 Thống Nhất | H37: Đông Hòa | I37: Hồ Chí Minh | M37: 22 | N37: 650 | O37: =N37*3 -> 1950 | P37: =O37*15% -> 292.5 | Q37: =SUM(O37:P37) -> 2242.5 | R37: =(O37*7*6)+(P37*7*2) -> 85995 | S37: 3 | T37: 6 | U37: 8 | V37: =T37+U37 -> 14 | W37: ON GOING | X37: 0 | Y37: =SUMIF($W$126,"ON GOING",V133) -> 0 | Z37: Shophouse, khu vui chơi | AA37: BVS, Bạo Lực, Kinh Dị, Bất động sản,..
A38: =ROW()-3 -> 35 | B38: AP | C38: =UPPER(SUBSTITUTE(E38, " ", "")) -> BCONSCITYBLOCKA2 | E38: Bcons City Block A2 | G38: 57-60 Thống Nhất | H38: Đông Hòa | I38: Hồ Chí Minh | M38: 22 | N38: 650 | O38: =N38*3 -> 1950 | P38: =O38*15% -> 292.5 | Q38: =SUM(O38:P38) -> 2242.5 | R38: =(O38*7*6)+(P38*7*2) -> 85995 | S38: 2 | T38: 4 | U38: 5 | V38: =T38+U38 -> 9 | W38: ON GOING | X38: 0 | Y38: =SUMIF($W$126,"ON GOING",V134) -> 0 | Z38: Shophouse, khu vui chơi | AA38: BVS, Bạo Lực, Kinh Dị, Bất động sản,..
A39: =ROW()-3 -> 36 | B39: AP | C39: =UPPER(SUBSTITUTE(E39, " ", "")) -> BCONSCITYBLOCKB1 | E39: Bcons City Block B1 | G39: 57-60 Thống Nhất | H39: Đông Hòa | I39: Hồ Chí Minh | M39: 22 | N39: 650 | O39: =N39*3 -> 1950 | P39: =O39*15% -> 292.5 | Q39: =SUM(O39:P39) -> 2242.5 | R39: =(O39*7*6)+(P39*7*2) -> 85995 | S39: 2 | T39: 4 | U39: 6 | V39: =T39+U39 -> 10 | W39: ON GOING | X39: 0 | Y39: =SUMIF($W$126,"ON GOING",V135) -> 0 | Z39: Shophouse, khu vui chơi | AA39: BVS, Bạo Lực, Kinh Dị, Bất động sản,..
A40: =ROW()-3 -> 37 | B40: AP | C40: =UPPER(SUBSTITUTE(E40, " ", "")) -> BCONSCITYBLOCKB2A | E40: Bcons City Block B2a | G40: 57-60 Thống Nhất | H40: Đông Hòa | I40: Hồ Chí Minh | M40: 22 | N40: 650 | O40: =N40*3 -> 1950 | P40: =O40*15% -> 292.5 | Q40: =SUM(O40:P40) -> 2242.5 | R40: =(O40*7*6)+(P40*7*2) -> 85995 | S40: 2 | T40: 4 | U40: 6 | V40: =T40+U40 -> 10 | W40: ON GOING | X40: 0 | Y40: =SUMIF($W$126,"ON GOING",V136) -> 0 | Z40: Shophouse, khu vui chơi | AA40: BVS, Bạo Lực, Kinh Dị, Bất động sản,..
...

Sheet Summary 
A1: TOTAL ON AIR
A2: Hệ thống | B2: Khu vực | C2: Số lượng toà nhà | D2: Traffic | E2: Số lượng thang máy | F2: DP (Digital Poster Inside Elevator) | G2: DP/LCD (Digital Poster Outside) | H2: GP (Giant Poster inside) | I2: GP (Giant Poster outside) | J2: Total | K2: Tỷ lệ (%)
A3: Digital Building | B3: Hồ Chí Minh | C3: ='List sale_DIGITAL BUILDING'!A47 -> 25 | D3: ='List sale_DIGITAL BUILDING'!Q47 -> 16311.6 | E3: ='List sale_DIGITAL BUILDING'!S47 -> 99 | F3: ='List sale_DIGITAL BUILDING'!T47 -> 138 | G3: ='List sale_DIGITAL BUILDING'!U47 -> 141 | H3: ='List sale_DIGITAL BUILDING'!X47 -> 6 | I3: ='List sale_DIGITAL BUILDING'!Y47 -> 58 | J3: =SUM(F3:G3) -> 279 | K3: =J3/J6 -> 0.38482759
B4: Hà Nội | C4: ='List sale_DIGITAL BUILDING'!A124 -> 24 | D4: ='List sale_DIGITAL BUILDING'!Q124 -> 24860.7 | E4: ='List sale_DIGITAL BUILDING'!S124 -> 98 | F4: ='List sale_DIGITAL BUILDING'!T124 -> 163 | G4: ='List sale_DIGITAL BUILDING'!U124 -> 81 | H4: ='List sale_DIGITAL BUILDING'!X124 -> 33 | I4: ='List sale_DIGITAL BUILDING'!Y124 -> 95 | J4: =SUM(F4:G4) -> 244 | K4: =J4/J6 -> 0.33655172
B5: Đà Nẵng | C5: ='List sale_DIGITAL BUILDING'!A127 -> 1 | D5: ='List sale_DIGITAL BUILDING'!Q127 -> 1000 | E5: ='List sale_DIGITAL BUILDING'!S127 -> 3 | F5: ='List sale_DIGITAL BUILDING'!T127 -> 6 | G5: ='List sale_DIGITAL BUILDING'!U127 -> 4 | H5: ='List sale_DIGITAL BUILDING'!X127 -> 0 | I5: ='List sale_DIGITAL BUILDING'!Y127 -> 0 | J5: =SUM(F5:G5) -> 10 | K5: =J5/J6 -> 0.013793103
A6: Total Nationwide | C6: =SUM(C3:C5) -> 50 | D6: =SUM(D3:D5) -> 42172.3 | E6: =SUM(E3:E5) -> 200 | F6: =SUM(F3:F5) -> 307 | G6: =SUM(G3:G5) -> 226 | H6: =SUM(H3:H5) -> 39 | I6: =SUM(I3:I5) -> 153 | J6: =SUM(F6:I6) -> 725 | K6: =SUM(K3:K5) -> 0.73517241
A7: TOTAL ON GOING
A8: Hệ thống | B8: Khu vực | C8: Số lượng toà nhà | D8: Traffic | E8: Số lượng thang máy | F8: DP (Digital Poster Inside Elevator) | G8: DP/LCD (Digital Poster Outside) | H8: GP (Giant Poster inside) | I8: GP (Giant Poster outside) | J8: Total | K8: Tỷ lệ (%)
A9: Digital Building | B9: Hồ Chí Minh | C9: ='List sale_DIGITAL BUILDING'!A48 -> 17 | D9: ='List sale_DIGITAL BUILDING'!O48 -> 19836 | E9: ='List sale_DIGITAL BUILDING'!S48 -> 54 | F9: ='List sale_DIGITAL BUILDING'!T48 -> 84 | G9: ='List sale_DIGITAL BUILDING'!U48 -> 93 | H9: ='List sale_DIGITAL BUILDING'!X48 -> 10 | I9: ='List sale_DIGITAL BUILDING'!Y48 -> 10 | J9: =SUM(F9:G9) -> 177 | K9: =J9/J12 -> 0.21532847
B10: Hà Nội | C10: ='List sale_DIGITAL BUILDING'!A125 -> 23 | D10: ='List sale_DIGITAL BUILDING'!O125 -> 37620 | E10: ='List sale_DIGITAL BUILDING'!S125 -> 204 | F10: ='List sale_DIGITAL BUILDING'!T125 -> 284 | G10: ='List sale_DIGITAL BUILDING'!U125 -> 305 | H10: ='List sale_DIGITAL BUILDING'!X125 -> 9 | I10: ='List sale_DIGITAL BUILDING'!Y125 -> 27 | J10: =SUM(F10:G10) -> 589 | K10: =J10/J12 -> 0.71654501
B11: Đà Nẵng | C11: ='List sale_DIGITAL BUILDING'!A128 -> 0 | D11: ='List sale_DIGITAL BUILDING'!O128 -> 0 | E11: ='List sale_DIGITAL BUILDING'!S128 -> 0 | F11: ='List sale_DIGITAL BUILDING'!T128 -> 0 | G11: ='List sale_DIGITAL BUILDING'!U128 -> 0 | H11: ='List sale_DIGITAL BUILDING'!X128 -> 0 | I11: ='List sale_DIGITAL BUILDING'!Y128 -> 0 | J11: =SUM(F11:G11) -> 0 | K11: =J11/J12 -> 0
A12: Total Nationwide | C12: =SUM(C9:C11) -> 40 | D12: =SUM(D9:D11) -> 57456 | E12: =SUM(E9:E11) -> 258 | F12: =SUM(F9:F11) -> 368 | G12: =SUM(G9:G11) -> 398 | H12: =SUM(H9:H11) -> 19 | I12: =SUM(I9:I11) -> 37 | J12: =SUM(F12:I12) -> 822 | K12: =SUM(K9:K11) -> 0.93187348

Sheet Hướng dẫn note màu 
A3: Chữ đỏ | B3: Có Dán GP
A4: Tô cam | B4: Màn hình on air
A5: Tô nhạt | B5: Màn hình on going
A6: Tô xám: | B6: Tạm ngưng khai thác
A7: Tô xanh lá: | B7: Trường khai thác mới
A8: Tô vàng: | B8: Có điều chỉnh thông tin
A9: Tô cam: | B9: Decal trong
